# Scala 异常处理

## try-catch-finally

Scala使用 `try-catch-finally`  来处理异常；

```scala
try {
	// ...
} catch {
    case ne: ArrayIndexOutOfBoundsException => ne.printStrackTrace()
	case e: Exception => {
		println(e)
	}
} finally {
    // ...
}
```

## throw 和 throws

`throw` 可以在代码中抛出确定的异常；

```scala
def func: Unit = {
	throw new RuntimeException()
}
```

`throws` 用于声明方法中可能会抛出的异常；方法的调用方需要处理异常或者抛出异常；

```scala
@throws(classOf[Exception])
def func: Unit = {
	throw new Exception()
}
```



